Workbook

Sheet index
C4: Company Name: | D4: Larsen & Toubro Limited (L&T)
C5: Parent Organization: | D5: It is an Independent Company
C6: Headquartes: | D6: Mumbai, Maharashtra, India
C7: Founder: | D7: Henning Holck-Larsen
D8: Søren Kristian Toubro
B13: Sheet No | C13: Sheet Name | D13: Link to Sheet
B14: 1 | C14: Index | D14: Index!A1
B15: 2 | C15: Income Statement Drivers | D15: Income Sheet Drivers'!A1
B16: 3 | C16: Balance Sheet Drivers | D16: Balance Sheet Drivers'!A1
B17: 4 | C17: forcast | D17: forcast!A1
B18: 5 | C18: Inocme Statement | D18: Income Statement'!A1
B19: 6 | C19: Balance Sheet | D19: Balance Sheet'!A1
B20: 7 | C20: Cashflow Statement | D20: Cashflow Statement'!A1
B21: 8 | C21: WACC | D21: Weigheted Average Cost Of Cap..'!A1
B22: 9 | C22: DCF | D22: Discounted Cash Flow Model'!A1
B23: 10 | C23: Comperative Analysis | D23: Comperative Analysis'!A1
B24: 11 | C24: Income Statement Raw Data | D24: IS!A1
B25: 12 | C25: Balance Sheet Raw Data | D25: BS!A1
B26: 13 | C26: Cashflow Statement Raw Data | D26: CF!A1

Sheet p&L drivers
B1: Scenario | C1: 1 | L1: Index!A1
B2: Drivers
B3: All the Figures In Crores
B4: Financial Year | C4: 44389 | D4: =C4+365 -> 44754 | E4: =D4+365 -> 45119 | F4: =E4+365 -> 45484 | G4: =F4+365 -> 45849 | H4: =G4+365 -> 46214 | I4: =H4+365 -> 46579 | J4: =I4+365 -> 46944 | K4: =J4+365 -> 47309 | L4: =K4+365 -> 47674
B5: Income Statement Drivers
B6: Revenue | C6: ='p&l'!C5 -> 135979.03 | D6: ='p&l'!D5 -> 156521.23 | E6: ='p&l'!E5 -> 183340.7 | F6: ='p&l'!F5 -> 221112.91 | G6: ='p&l'!G5 -> 255734.45
B7: Revenue Growth (Y-O-Y %) | C7: =0 -> 0 | D7: =forcast!S12 -> 0.15106744 | E7: =forcast!S13 -> 0.17135081 | F7: =forcast!S14 -> 0.20602048 | G7: =forcast!S15 -> 0.15657605 | H7: =CHOOSE($C$1,H8,H9,H10) -> 0.12465368 | I7: =CHOOSE($C$1,I8,I9,I10) -> 0.12139912 | J7: =CHOOSE($C$1,J8,J9,J10) -> 0.11357381 | K7: =CHOOSE($C$1,K8,K9,K10) -> 0.097773554 | L7: =CHOOSE($C$1,L8,L9,L10) -> 0.088263
B8: Scenario 1 (Pessimistic) | H8: =H9-1% -> 0.12465368 | I8: =I9-1% -> 0.12139912 | J8: =J9-1% -> 0.11357381 | K8: =K9-1% -> 0.097773554 | L8: =L9-1% -> 0.088263
B9: Scenario 2 (Realistic) | H9: =forcast!N22 -> 0.13465368 | I9: =forcast!N23 -> 0.13139912 | J9: =forcast!N24 -> 0.12357381 | K9: =forcast!N25 -> 0.10777355 | L9: =forcast!N26 -> 0.098263
B10: Scenario 3 (Optimistic) | H10: =H9+1% -> 0.14465368 | I10: =I9+1% -> 0.14139912 | J10: =J9+1% -> 0.13357381 | K10: =K9+1% -> 0.11777355 | L10: =L9+1% -> 0.108263
B12: Cost of Goods Sold (COGS)
B13: Cogs | C13: ='income statement'!C9 -> 79009.86 | D13: ='income statement'!D9 -> 93785.97 | E13: ='income statement'!E9 -> 110588.83 | F13: ='income statement'!F9 -> 140313.92 | G13: ='income statement'!G9 -> 164670.67 | H13: =CHOOSE($C$1,H14,H15,H16) -> 0.64238305 | I13: =CHOOSE($C$1,I14,I15,I16) -> 0.64865077 | J13: =CHOOSE($C$1,J14,J15,J16) -> 0.6525429 | K13: =CHOOSE($C$1,K14,K15,K16) -> 0.65641397 | L13: =CHOOSE($C$1,L14,L15,L16) -> 0.65478069
B14: Scenario 1 (Pessimistic) | H14: =H15+3% -> 0.64238305 | I14: =I15+3% -> 0.64865077 | J14: =J15+3% -> 0.6525429 | K14: =K15+3% -> 0.65641397 | L14: =L15+3% -> 0.65478069
B15: COGS % of Revenue (Scenario 2 (Base ) | C15: =C13/C6 -> 0.58104444 | D15: =D13/D6 -> 0.59919009 | E15: =E13/E6 -> 0.60318756 | F15: =F13/F6 -> 0.63458041 | G15: =G13/G6 -> 0.64391274 | H15: =AVERAGE(C15:G15) -> 0.61238305 | I15: =AVERAGE(D15:H15) -> 0.61865077 | J15: =AVERAGE(E15:I15) -> 0.6225429 | K15: =AVERAGE(F15:J15) -> 0.62641397 | L15: =AVERAGE(G15:K15) -> 0.62478069
B16: Scenario 3 (Optimistic) | H16: =H15-2% -> 0.59238305 | I16: =I15-2% -> 0.59865077 | J16: =J15-2% -> 0.6025429 | K16: =K15-2% -> 0.60641397 | L16: =L15-2% -> 0.60478069
B18: Operating & Non-Operating Expenses
B19: Employee benefits expense (Growth Y-O-Y) | D19: ='income statement'!D11/'income statement'!C11-1 -> 0.20132854 | E19: ='income statement'!E11/'income statement'!D11-1 -> 0.25158735 | F19: ='income statement'!F11/'income statement'!E11-1 -> 0.10632822 | G19: ='income statement'!G11/'income statement'!F11-1 -> 0.13596117 | H19: =AVERAGE(D19:G19) -> 0.17380132 | I19: =H19 -> 0.17380132 | J19: =I19 -> 0.17380132 | K19: =J19 -> 0.17380132 | L19: =K19 -> 0.17380132
B20: Sales, administration and other expenses (Growth Y-O-Y) | D20: ='income statement'!D13/'income statement'!C13-1 -> -0.0080417904 | E20: ='income statement'!E13/'income statement'!D13-1 -> -0.0083617436 | F20: ='income statement'!F13/'income statement'!E13-1 -> 0.18969769 | G20: ='income statement'!G13/'income statement'!F13-1 -> 0.10928727 | H20: =G20 -> 0.10928727 | I20: =H20 -> 0.10928727 | J20: =I20 -> 0.10928727 | K20: =J20 -> 0.10928727 | L20: =K20 -> 0.10928727
B22: Finance cost of financial services business and finance lease activity | C22: ='income statement'!C12 -> 7691.04 | D22: ='income statement'!D12 -> 5952.54 | E22: ='income statement'!E12 -> 6026.44 | F22: ='income statement'!F12 -> 5714.9 | G22: ='income statement'!G12 -> 6302.23 | H22: =G22 -> 6302.23 | I22: =H22 -> 6302.23 | J22: =I22 -> 6302.23 | K22: =J22 -> 6302.23 | L22: =K22 -> 6302.23
B24: Tax Expenses | C24: ='income statement'!C20 -> 4010.82 | D24: ='income statement'!D20 -> 4216.61 | E24: ='income statement'!E20 -> 4484.16 | F24: ='income statement'!F20 -> 4947.39 | G24: ='income statement'!G20 -> 5891.4 | H24: =H25*H26 -> 7427.506 | I24: =I25*I26 -> 7501.3796 | J24: =J25*J26 -> 7366.1959 | K24: =K25*K26 -> 6456.9539 | L24: =L25*L26 -> 5421.6709
B25: Profit Before Tax | C25: ='income statement'!C19 -> 12235.8 | D25: ='income statement'!D19 -> 14410.73 | E25: ='income statement'!E19 -> 16973.04 | F25: ='income statement'!F19 -> 20423.5 | G25: ='income statement'!G19 -> 23104.01 | H25: ='income statement'!H19 -> 28113.929 | I25: ='income statement'!I19 -> 28393.549 | J25: ='income statement'!J19 -> 27881.864 | ... L25: ='income statement'!L19 -> 20521.622
B26: Tax Rate | C26: =C24/C25 -> 0.32779385 | D26: =D24/D25 -> 0.29260211 | E26: =E24/E25 -> 0.2641931 | F26: =F24/F25 -> 0.24224007 | G26: =G24/G25 -> 0.2549947 | H26: =MEDIAN(C26:G26) -> 0.2641931 | I26: =H26 -> 0.2641931 | J26: =I26 -> 0.2641931 | K26: =J26 -> 0.2641931 | L26: =K26 -> 0.2641931

Sheet bs drivers
B2: Balance Sheet Drivers
B3: All the Figures In Crores
B4: Financial Year | C4: 44389 | D4: =C4+365 -> 44754 | E4: =D4+365 -> 45119 | F4: =E4+365 -> 45484 | G4: =F4+365 -> 45849 | H4: =G4+365 -> 46214 | I4: =H4+365 -> 46579 | J4: =I4+365 -> 46944 | K4: =J4+365 -> 47309 | L4: =K4+365 -> 47674
B5: Current Assets
B6: Inventories | C6: ='balance sheet1'!C7 -> 5820.54 | D6: ='balance sheet1'!D7 -> 5943.32 | E6: ='balance sheet1'!E7 -> 6828.78 | F6: ='balance sheet1'!F7 -> 6620.19 | G6: ='balance sheet1'!G7 -> 7670.55 | H6: =H7*H8 -> 11408.643 | I6: =I7*I8 -> 12918.469 | J6: =J7*J8 -> 14471.988 | K6: =K7*K8 -> 15981.212 | L6: =L7*L8 -> 17348.487
B7: COGS | C7: ='income statement'!C9 -> 79009.86 | D7: ='income statement'!D9 -> 93785.97 | E7: ='income statement'!E9 -> 110588.83 | F7: ='income statement'!F9 -> 140313.92 | G7: ='income statement'!G9 -> 164670.67 | H7: ='income statement'!H9 -> 184757.52 | I7: ='income statement'!I9 -> 209208.44 | J7: ='income statement'!J9 -> 234366.93 | ... L7: ='income statement'!L9 -> 280950.46
B8: Inventories (as a % of COGS) | C8: =C6/C7 -> 0.073668527 | D8: =D6/D7 -> 0.063371099 | E8: =E6/E7 -> 0.061749274 | F8: =F6/F7 -> 0.047181278 | G8: =G6/G7 -> 0.046581155 | H8: =MEDIAN(C8:G8) -> 0.061749274 | I8: =MEDIAN(D8:H8) -> 0.061749274 | J8: =MEDIAN(E8:I8) -> 0.061749274 | K8: =MEDIAN(F8:J8) -> 0.061749274 | L8: =MEDIAN(G8:K8) -> 0.061749274
B10: Investments | C10: ='balance sheet1'!C8 -> 31011.23 | D10: ='balance sheet1'!D8 -> 29799.58 | E10: ='balance sheet1'!E8 -> 35573.42 | F10: ='balance sheet1'!F8 -> 34957.63 | G10: ='balance sheet1'!G8 -> 43360.62 | H10: =H11*H12 -> 54078.47 | I10: =I11*I12 -> 60643.548 | J10: =J11*J12 -> 67531.067 | K10: =K11*K12 -> 74133.82 | L10: =L11*L12 -> 80677.093
B11: Revenue | C11: ='income statement'!C6 -> 135979.03 | D11: ='income statement'!D6 -> 156521.23 | E11: ='income statement'!E6 -> 183340.7 | F11: ='income statement'!F6 -> 221112.91 | G11: ='income statement'!G6 -> 255734.45 | H11: ='income statement'!H6 -> 287612.69 | I11: ='income statement'!I6 -> 322528.62 | J11: ='income statement'!J6 -> 359159.42 | ... L11: ='income statement'!L6 -> 429075.67
B12: Investments (as a % of Revenue) | C12: =C10/C11 -> 0.22805891 | D12: =D10/D11 -> 0.19038682 | E12: =E10/E11 -> 0.19402904 | F12: =F10/F11 -> 0.15809855 | G12: =G10/G11 -> 0.1695533 | H12: =AVERAGE($C$12:$G$12) -> 0.18802533 | I12: =AVERAGE($C$12:$G$12) -> 0.18802533 | J12: =AVERAGE($C$12:$G$12) -> 0.18802533 | K12: =AVERAGE($C$12:$G$12) -> 0.18802533 | L12: =AVERAGE($C$12:$G$12) -> 0.18802533
B14: Trade receivables | C14: ='balance sheet1'!C9 -> 42229.78 | D14: ='balance sheet1'!D9 -> 46139.32 | E14: ='balance sheet1'!E9 -> 44731.53 | F14: ='balance sheet1'!F9 -> 48770.95 | G14: ='balance sheet1'!G9 -> 53713.68 | H14: =H15*H16 -> 73624.739 | I14: =I15*I16 -> 82562.718 | J14: =J15*J16 -> 91939.68 | K14: =K15*K16 -> 100928.95 | L14: =L15*L16 -> 109837.24
B15: Revenue | C15: =C11 -> 135979.03 | D15: =D11 -> 156521.23 | E15: =E11 -> 183340.7 | F15: =F11 -> 221112.91 | G15: =G11 -> 255734.45 | H15: =H11 -> 287612.69 | I15: =I11 -> 322528.62 | J15: =J11 -> 359159.42 | ... L15: =L11 -> 429075.67
B16: Trade Receivables (as a % of Revenue) | C16: =C14/C15 -> 0.31056097 | D16: =D14/D15 -> 0.29477995 | E16: =E14/E15 -> 0.24398036 | F16: =F14/F15 -> 0.22057034 | G16: =G14/G15 -> 0.21003693 | H16: =AVERAGE($C$16:$G$16) -> 0.25598571 | I16: =AVERAGE($C$16:$G$16) -> 0.25598571 | J16: =AVERAGE($C$16:$G$16) -> 0.25598571 | K16: =AVERAGE($C$16:$G$16) -> 0.25598571 | L16: =AVERAGE($C$16:$G$16) -> 0.25598571
B18: Other bank balances | C18: ='balance sheet1'!C11 -> 2867.98 | D18: ='balance sheet1'!D11 -> 5182.93 | E18: ='balance sheet1'!E11 -> 5592.91 | F18: ='balance sheet1'!F11 -> 3399.89 | G18: ='balance sheet1'!G11 -> 10778.34 | H18: =H19*H20 -> 8181.6054 | I18: =I19*I20 -> 9174.8451 | J18: =J19*J20 -> 10216.867 | K18: =K19*K20 -> 11215.807 | L18: =L19*L20 -> 12205.747
B19: Revenue | C19: =C15 -> 135979.03 | D19: =D15 -> 156521.23 | E19: =E15 -> 183340.7 | F19: =F15 -> 221112.91 | G19: =G15 -> 255734.45 | H19: =H15 -> 287612.69 | I19: =I15 -> 322528.62 | J19: =J15 -> 359159.42 | ... L19: =L15 -> 429075.67
B20: Other Bank Balances (As a % of Revenue) | C20: =C18/C19 -> 0.02109134 | D20: =D18/D19 -> 0.033113272 | E20: =E18/E19 -> 0.030505556 | F20: =F18/F19 -> 0.015376262 | G20: =G18/G19 -> 0.04214661 | H20: =AVERAGE($C$20:$G$20) -> 0.028446608 | I20: =AVERAGE($C$20:$G$20) -> 0.028446608 | J20: =AVERAGE($C$20:$G$20) -> 0.028446608 | K20: =AVERAGE($C$20:$G$20) -> 0.028446608 | L20: =AVERAGE($C$20:$G$20) -> 0.028446608
B22: Loans towards financing activities | C22: ='balance sheet1'!C12 -> 41379.03 | D22: ='balance sheet1'!D12 -> 42269.2 | E22: ='balance sheet1'!E12 -> 40460.55 | F22: ='balance sheet1'!F12 -> 34814.59 | G22: ='balance sheet1'!G12 -> 36077.51 | H22: =G22 -> 36077.51 | I22: =H22 -> 36077.51 | J22: =I22 -> 36077.51 | K22: =J22 -> 36077.51 | L22: =K22 -> 36077.51
B24: Other loans | C24: ='balance sheet1'!C13 -> 235.35 | D24: ='balance sheet1'!D13 -> 280.34 | E24: ='balance sheet1'!E13 -> 251.15 | F24: ='balance sheet1'!F13 -> 106.54 | G24: ='balance sheet1'!G13 -> 416.85 | H24: =G24 -> 416.85 | I24: =H24 -> 416.85 | J24: =I24 -> 416.85 | K24: =J24 -> 416.85 | L24: =K24 -> 416.85
B26: Other financial assets | C26: ='balance sheet1'!C14 -> 3251.68 | D26: ='balance sheet1'!D14 -> 3655.82 | E26: ='balance sheet1'!E14 -> 4930.1 | F26: ='balance sheet1'!F14 -> 5563.92 | G26: ='balance sheet1'!G14 -> 5419.89 | H26: =G26 -> 5419.89 | I26: =H26 -> 5419.89 | J26: =I26 -> 5419.89 | K26: =J26 -> 5419.89 | L26: =K26 -> 5419.89
B28: Other current assets | C28: ='balance sheet1'!C15 -> 54791.48 | D28: ='balance sheet1'!D15 -> 60331.55 | E28: ='balance sheet1'!E15 -> 65920.39 | F28: ='balance sheet1'!F15 -> 71391.03 | G28: ='balance sheet1'!G15 -> 75559.83 | H28: =G28 -> 75559.83 | I28: =H28 -> 75559.83 | J28: =I28 -> 75559.83 | K28: =J28 -> 75559.83 | L28: =K28 -> 75559.83
B30: Non-Current Assets
B31: Property, plant & equipment | H31: 0.0552 | I31: 0.0563 | J31: 0.0573 | K31: 0.0583 | L31: 0.059
B32: Investment property | H32: 0 | I32: 0 | J32: 0 | K32: 0 | L32: 0
B33: Other intangible assets | H33: 0 | I33: 0 | J33: 0 | K33: 0 | L33: 0
B34: Right-of-use assets | H34: 0.0619 | I34: 0.0612 | J34: 0.0608 | K34: 0.0603 | L34: 0.0599
B35: Capital work-in-progress | H35: 0.2506 | I35: 0.2507 | J35: 0.2508 | K35: 0.2509 | L35: 0.2511
B36: Investment property under construction | H36: 0 | I36: 0 | J36: 0 | K36: 0 | L36: 0
B37: Goodwill | H37: =I60 -> 0 | I37: =J60 -> 0 | J37: =K60 -> 0 | K37: =L60 -> 0 | L37: =M60 -> 0
B38: Intangible assets under development | H38: 0.1481 | I38: 0.1623 | J38: 0.1634 | K38: 0.1631 | L38: 0.1613
B39: Investments in joint ventures & associa | H39: 0 | I39: 0 | J39: 0 | K39: 0 | L39: 0
B40: Other investments | H40: 0.1131 | I40: 0.1131 | J40: 0.1131 | K40: 0.1131 | L40: 0.1131
B41: Loans towards financing activities | H41: 0.0453 | I41: 0.0453 | J41: 0.0453 | K41: 0.0453 | L41: 0.0453
B42: Other loans | H42: 0.1913 | I42: 0.1913 | J42: 0.1913 | K42: 0.1913 | L42: 0.1913
B43: Other financial assets | H43: 0.0702 | I43: 0.0702 | J43: 0.0702 | K43: 0.0702 | L43: 0.0702
B44: Deferred tax assets (net) | H44: 0.089 | I44: 0.089 | J44: 0.089 | K44: 0.089 | L44: 0.089
B45: Current Tax Assets (net) | H45: 0.1265 | I45: 0.1265 | J45: 0.1265 | K45: 0.1265 | L45: 0.1265
B46: Other non-current assets | H46: 0 | I46: 0 | J46: 0 | K46: 0 | L46: 0
B52: Property, Plant & Equipment | H52: =G58 -> 14128.56 | I52: =H58 -> 14043.766 | J52: =I58 -> 13974.033 | K52: =J58 -> 13932.585 | L52: =K58 -> 13904.398
B53: Capex Growth Rate | H53: =H31 -> 0.0552 | I53: =I31 -> 0.0563 | J53: =J31 -> 0.0573 | K53: =K31 -> 0.0583 | L53: =L31 -> 0.059
B54: Capex | H54: =H52*H53 -> 779.89651 | I54: =I52*I53 -> 790.66403 | J54: =J52*J53 -> 800.7121 | K54: =K52*K53 -> 812.26969 | L54: =L52*L53 -> 820.35947
...

Sheet forcast
D4: Sr.no | E4: Years | F4: Revenue | G4: growth | Q4: regration - function
D5: 1 | E5: 42460 | F5: 101975 | G5: 0 | P5: S.no | Q5: Years | R5: Sales
D6: 2 | E6: 42825 | F6: 110011 | G6: =F6/F5-1 -> 0.078803628 | P6: =1 -> 1 | Q6: 42460 | R6: 101975 | S6: 0
D7: 3 | E7: 43190 | F7: 119862 | G7: =F7/F6-1 -> 0.089545591 | P7: =P6+1 -> 2 | Q7: 42825 | R7: 110011 | S7: =R7/R6-1 -> 0.078803628
D8: 4 | E8: 43555 | F8: 135220 | G8: =F8/F7-1 -> 0.12813068 | P8: =P7+1 -> 3 | Q8: 43190 | R8: 119862 | S8: =R8/R7-1 -> 0.089545591
D9: 5 | E9: 43921 | F9: 145452 | G9: =F9/F8-1 -> 0.07566928 | P9: =P8+1 -> 4 | Q9: 43555 | R9: 135220 | S9: =R9/R8-1 -> 0.12813068
D10: 6 | E10: 44286 | F10: 135979 | G10: =F10/F9-1 -> -0.065128015 | L10: CAGR | P10: =P9+1 -> 5 | Q10: 43921 | R10: 145452 | S10: =R10/R9-1 -> 0.07566928
D11: 7 | E11: 44651 | F11: 156521 | G11: =F11/F10-1 -> 0.15106744 | K11: S.no | L11: Years | M11: Sales | P11: =P10+1 -> 6 | Q11: 44286 | R11: 135979 | S11: =R11/R10-1 -> -0.065128015
D12: 8 | E12: 45016 | F12: 183341 | G12: =F12/F11-1 -> 0.17135081 | K12: =1 -> 1 | L12: 42460 | M12: 101975 | P12: =P11+1 -> 7 | Q12: 44651 | R12: 156521 | S12: =R12/R11-1 -> 0.15106744
D13: 9 | E13: 45382 | F13: 221113 | G13: =F13/F12-1 -> 0.20602048 | K13: =K12+1 -> 2 | L13: 42825 | M13: 110011 | P13: =P12+1 -> 8 | Q13: 45016 | R13: 183341 | S13: =R13/R12-1 -> 0.17135081
D14: 10 | E14: 45747 | F14: 255734 | G14: =F14/F13-1 -> 0.15657605 | K14: =K13+1 -> 3 | L14: 43190 | M14: 119862 | P14: =P13+1 -> 9 | Q14: 45382 | R14: 221113 | S14: =R14/R13-1 -> 0.20602048
D15: 11 | E15: 46112 | F15: =F14*(1+G15) -> 299529.39 | G15: =AVERAGE(G11:G14) -> 0.17125369 | K15: =K14+1 -> 4 | L15: 43555 | M15: 135220 | P15: =P14+1 -> 10 | Q15: 45747 | R15: 255734 | S15: =R15/R14-1 -> 0.15657605
D16: 12 | E16: 46477 | F16: =F15*(1+G16) -> 352336.5 | G16: =AVERAGE(G12:G15) -> 0.17630026 | K16: =K15+1 -> 5 | L16: 43921 | M16: 145452 | P16: =P15+1 -> 11 | Q16: 46112 | R16: =_xlfn.FORECAST.LINEAR(P16,R6:R15,P6:P15) -> 240966.47 | S16: =R16/R15-1 -> -0.057745678
D17: 13 | E17: 46843 | F17: =F16*(1+G17) -> 414889.48 | G17: =AVERAGE(G13:G16) -> 0.17753762 | K17: =K16+1 -> 6 | L17: 44286 | M17: 135979 | N17: pv | P17: =P16+1 -> 12 | Q17: 46477 | R17: =_xlfn.FORECAST.LINEAR(P17,R7:R16,P7:P16) -> 260199.19 | S17: =R17/R16-1 -> 0.079814923
D18: 14 | E18: 47208 | F18: =F17*(1+G18) -> 485593.67 | G18: =AVERAGE(G14:G17) -> 0.17041691 | K18: =K17+1 -> 7 | L18: 44651 | M18: 156521 | P18: =P17+1 -> 13 | Q18: 46843 | R18: =_xlfn.FORECAST.LINEAR(P18,R8:R17,P8:P17) -> 280001.83 | S18: =R18/R17-1 -> 0.076105709
D19: 15 | E19: 47573 | F19: =F18*(1+G19) -> 570027.29 | G19: =AVERAGE(G15:G18) -> 0.17387712 | K19: =K18+1 -> 8 | L19: 45016 | M19: 183341 | P19: =P18+1 -> 14 | Q19: 47208 | R19: =_xlfn.FORECAST.LINEAR(P19,R9:R18,P9:P18) -> 300339.92 | S19: =R19/R18-1 -> 0.072635556
K20: =K19+1 -> 9 | L20: 45382 | M20: 221113 | P20: =P19+1 -> 15 | Q20: 47573 | R20: =_xlfn.FORECAST.LINEAR(P20,R10:R19,P10:P19) -> 322232.72 | S20: =R20/R19-1 -> 0.072893414
K21: =K20+1 -> 10 | L21: 45747 | M21: 255734 | N21: fv
K22: =K21+1 -> 11 | L22: 46112 | M22: =M21*(1+N22) -> 290169.52 | N22: =_xlfn.RRI(5,M17,M21) -> 0.13465368
K23: =K22+1 -> 12 | L23: 46477 | M23: =M22*(1+N23) -> 328297.54 | N23: =_xlfn.RRI(5,M18,M22) -> 0.13139912
K24: =K23+1 -> 13 | L24: 46843 | M24: =M23*(1+N24) -> 368866.52 | N24: =_xlfn.RRI(5,M19,M23) -> 0.12357381
K25: =K24+1 -> 14 | L25: 47208 | M25: =M24*(1+N25) -> 408620.58 | N25: =_xlfn.RRI(5,M20,M24) -> 0.10777355
K26: =K25+1 -> 15 | L26: 47573 | M26: =M25*(1+N26) -> 448772.86 | N26: =_xlfn.RRI(5,M21,M25) -> 0.098263

Sheet 3 statement model->

Sheet income statement
L2: Index!A1
B3: Income Statement
B4: All the Figures In Crores
B5: Financial Year | C5: 44389 | D5: =C5+365 -> 44754 | E5: =D5+365 -> 45119 | F5: =E5+365 -> 45484 | G5: =F5+365 -> 45849 | H5: =G5+365 -> 46214 | I5: =H5+365 -> 46579 | J5: =I5+365 -> 46944 | K5: =J5+365 -> 47309 | L5: =K5+365 -> 47674
B6: Revenue from operations | C6: ='p&l'!C5 -> 135979.03 | D6: ='p&l'!D5 -> 156521.23 | E6: ='p&l'!E5 -> 183340.7 | F6: ='p&l'!F5 -> 221112.91 | G6: ='p&l'!G5 -> 255734.45 | H6: =G6*(1+'p&L drivers'!H7) -> 287612.69 | I6: =H6*(1+'p&L drivers'!I7) -> 322528.62 | J6: =I6*(1+'p&L drivers'!J7) -> 359159.42 | K6: =J6*(1+'p&L drivers'!K7) -> 394275.71 | L6: =K6*(1+'p&L drivers'!L7) -> 429075.67
B7: Other income net | C7: ='p&l'!C6 -> 3429.35 | D7: ='p&l'!D6 -> 2267.08 | E7: ='p&l'!E6 -> 2929.17 | F7: ='p&l'!F6 -> 4158.03 | G7: ='p&l'!G6 -> 4124.82 | H7: =G7 -> 4124.82 | I7: =H7 -> 4124.82 | J7: =I7 -> 4124.82 | K7: =J7 -> 4124.82 | L7: =K7 -> 4124.82
B8: Total Income | C8: =SUM(C6:C7) -> 139408.38 | D8: =SUM(D6:D7) -> 158788.31 | E8: =SUM(E6:E7) -> 186269.87 | F8: =SUM(F6:F7) -> 225270.94 | G8: =SUM(G6:G7) -> 259859.27 | H8: =SUM(H6:H7) -> 291737.51 | I8: =SUM(I6:I7) -> 326653.44 | J8: =SUM(J6:J7) -> 363284.24 | ... L8: =SUM(L6:L7) -> 433200.49
B9: COGS | C9: =SUM('p&l'!C9:C15) -> 79009.86 | D9: =SUM('p&l'!D9:D15) -> 93785.97 | E9: =SUM('p&l'!E9:E15) -> 110588.83 | F9: =SUM('p&l'!F9:F15) -> 140313.92 | G9: =SUM('p&l'!G9:G15) -> 164670.67 | H9: =H6*'p&L drivers'!H13 -> 184757.52 | I9: =I6*'p&L drivers'!I13 -> 209208.44 | J9: =J6*'p&L drivers'!J13 -> 234366.93 | K9: =K6*'p&L drivers'!K13 -> 258808.09 | L9: =L6*'p&L drivers'!L13 -> 280950.46
B10: Gross Profit | C10: =C8-C9 -> 60398.52 | D10: =D8-D9 -> 65002.34 | E10: =E8-E9 -> 75681.04 | F10: =F8-F9 -> 84957.02 | G10: =G8-G9 -> 95188.6 | H10: =H8-H9 -> 106979.99 | I10: =I8-I9 -> 117445 | J10: =J8-J9 -> 128917.31 | ... L10: =L8-L9 -> 152250.03
B11: Employee benefits expense | C11: ='p&l'!C18 -> 24750.54 | D11: ='p&l'!D18 -> 29733.53 | E11: ='p&l'!E18 -> 37214.11 | F11: ='p&l'!F18 -> 41171.02 | G11: ='p&l'!G18 -> 46768.68 | H11: =G11*(1+'p&L drivers'!H19) -> 54897.138 | I11: =H11*(1+'p&L drivers'!I19) -> 64438.333 | J11: =I11*(1+'p&L drivers'!J19) -> 75637.8 | K11: =J11*(1+'p&L drivers'!K19) -> 88783.75 | L11: =K11*(1+'p&L drivers'!L19) -> 104214.48
B12: Finance cost of financial services business and finance lease activity | C12: ='p&l'!C16 -> 7691.04 | D12: ='p&l'!D16 -> 5952.54 | E12: ='p&l'!E16 -> 6026.44 | F12: ='p&l'!F16 -> 5714.9 | G12: ='p&l'!G16 -> 6302.23 | H12: ='p&L drivers'!H22 -> 6302.23 | I12: ='p&L drivers'!I22 -> 6302.23 | J12: ='p&L drivers'!J22 -> 6302.23 | K12: ='p&L drivers'!K22 -> 6302.23 | L12: ='p&L drivers'!L22 -> 6302.23
B13: Sales, administration and other expenses | C13: ='p&l'!C19 -> 8903.49 | D13: ='p&l'!D19 -> 8831.89 | E13: ='p&l'!E19 -> 8758.04 | F13: ='p&l'!F19 -> 10419.42 | G13: ='p&l'!G19 -> 11558.13 | H13: =G13*(1+'p&L drivers'!H20) -> 12821.287 | I13: =H13*(1+'p&L drivers'!I20) -> 14222.49 | J13: =I13*(1+'p&L drivers'!J20) -> 15776.827 | K13: =J13*(1+'p&L drivers'!K20) -> 17501.034 | L13: =K13*(1+'p&L drivers'!L20) -> 19413.674
B14: Total Expense | C14: =SUM(C11:C13) -> 41345.07 | D14: =SUM(D11:D13) -> 44517.96 | E14: =SUM(E11:E13) -> 51998.59 | F14: =SUM(F11:F13) -> 57305.34 | G14: =SUM(G11:G13) -> 64629.04 | H14: =SUM(H11:H13) -> 74020.655 | I14: =SUM(I11:I13) -> 84963.053 | J14: =SUM(J11:J13) -> 97716.858 | ... L14: =SUM(L11:L13) -> 129930.39
B15: EBITDA | C15: =C10-C14 -> 19053.45 | D15: =D10-D14 -> 20484.38 | E15: =E10-E14 -> 23682.45 | F15: =F10-F14 -> 27651.68 | G15: =G10-G14 -> 30559.56 | H15: =H10-H14 -> 32959.339 | I15: =I10-I14 -> 32481.949 | J15: =J10-J14 -> 31200.452 | ... L15: =L10-L14 -> 22319.642
B16: Depreciation, amortisation, impairment and obsolescence | C16: ='p&l'!C21 -> 2904.21 | D16: ='p&l'!D21 -> 2947.95 | E16: ='p&l'!E21 -> 3502.25 | F16: ='p&l'!F21 -> 3682.33 | G16: ='p&l'!G21 -> 4121.18 | H16: ='bs drivers'!H186 -> 1111.1423 | I16: ='bs drivers'!I186 -> 1100.9859 | J16: ='bs drivers'!J186 -> 1078.0277 | K16: ='bs drivers'!K186 -> 1071.4437 | L16: ='bs drivers'!L186 -> 1051.1668
B17: EBIT | C17: =C15-C16 -> 16149.24 | D17: =D15-D16 -> 17536.43 | E17: =E15-E16 -> 20180.2 | F17: =F15-F16 -> 23969.35 | G17: =G15-G16 -> 26438.38 | H17: =H15-H16 -> 31848.196 | I17: =I15-I16 -> 31380.963 | J17: =J15-J16 -> 30122.424 | ... L17: =L15-L16 -> 21268.476
B18: Finance costs | C18: ='p&l'!C20 -> 3913.44 | D18: ='p&l'!D20 -> 3125.7 | E18: ='p&l'!E20 -> 3207.16 | F18: ='p&l'!F20 -> 3545.85 | G18: ='p&l'!G20 -> 3334.37 | H18: ='bs drivers'!H225 -> 3734.2674 | I18: ='bs drivers'!I225 -> 2987.4139 | J18: ='bs drivers'!J225 -> 2240.5604 | K18: ='bs drivers'!K225 -> 1493.707 | L18: ='bs drivers'!L225 -> 746.85348
B19: Profit before tax | C19: =C17-C18 -> 12235.8 | D19: =D17-D18 -> 14410.73 | E19: =E17-E18 -> 16973.04 | F19: =F17-F18 -> 20423.5 | G19: =G17-G18 -> 23104.01 | H19: =H17-H18 -> 28113.929 | I19: =I17-I18 -> 28393.549 | J19: =J17-J18 -> 27881.864 | ... L19: =L17-L18 -> 20521.622
B20: Tax expense | C20: ='p&l'!C26 -> 4010.82 | D20: ='p&l'!D26 -> 4216.61 | E20: ='p&l'!E26 -> 4484.16 | F20: ='p&l'!F26 -> 4947.39 | G20: ='p&l'!G26 -> 5891.4 | H20: ='p&L drivers'!H24 -> 7427.506 | I20: ='p&L drivers'!I24 -> 7501.3796 | J20: ='p&L drivers'!J24 -> 7366.1959 | K20: ='p&L drivers'!K24 -> 6456.9539 | L20: ='p&L drivers'!L24 -> 5421.6709
B21: Profit after tax | C21: =C19-C20 -> 8224.98 | D21: =D19-D20 -> 10194.12 | E21: =E19-E20 -> 12488.88 | F21: =F19-F20 -> 15476.11 | G21: =G19-G20 -> 17212.61 | H21: =H19-H20 -> 20686.423 | I21: =I19-I20 -> 20892.169 | J21: =J19-J20 -> 20515.668 | ... L21: =L19-L20 -> 15099.951
B22: Share in profit/(loss) after tax of joint ventures/associates (net) | C22: ='p&l'!C28 -> 14.4 | D22: ='p&l'!D28 -> 128.19 | E22: ='p&l'!E28 -> -94.25 | F22: ='p&l'!F28 -> -22.62 | G22: ='p&l'!G28 -> -14.06 | H22: =G22 -> -14.06 | I22: =H22 -> -14.06 | J22: =I22 -> -14.06 | K22: =J22 -> -14.06 | L22: =K22 -> -14.06
B23: Profit for the period (Net Income) | C23: =C21+C22 -> 8239.38 | D23: =D21+D22 -> 10322.31 | E23: =E21+E22 -> 12394.63 | F23: =F21+F22 -> 15453.49 | G23: =G21+G22 -> 17198.55 | H23: =H21+H22 -> 20672.363 | I23: =I21+I22 -> 20878.109 | J23: =J21+J22 -> 20501.608 | ... L23: =L21+L22 -> 15085.891
B24: Dividend Paid | C24: =C21*C28 -> 3618.9912 | D24: =D21*D28 -> 3669.8832 | E24: =E21*E28 -> 3996.4416 | F24: =F21*F28 -> 5571.3996 | G24: =G21*G28 -> 5335.9091 | H24: =H21*H28 -> 7405.7395 | I24: =I21*I28 -> 7479.3966 | J24: =J21*J28 -> 7344.6091 | ... L24: =L21*L28 -> 5405.7826
B25: Transfer to Reserve | C25: =C21-C24 -> 4605.9888 | D25: =D21-D24 -> 6524.2368 | E25: =E21-E24 -> 8492.4384 | F25: =F21-F24 -> 9904.7104 | G25: =G21-G24 -> 11876.701 | H25: =H21-H24 -> 13280.684 | I25: =I21-I24 -> 13412.773 | J25: =J21-J24 -> 13171.059 | ... L25: =L21-L24 -> 9694.1687
B28: Dividend Payout % | C28: 0.44 | D28: 0.36 | E28: 0.32 | F28: 0.36 | G28: 0.31 | H28: =AVERAGE($C$28:$G$28) -> 0.358 | I28: =AVERAGE($C$28:$G$28) -> 0.358 | J28: =AVERAGE($C$28:$G$28) -> 0.358 | K28: =AVERAGE($C$28:$G$28) -> 0.358 | L28: =AVERAGE($C$28:$G$28) -> 0.358
B29: Adjustment Into R&S | D29: =D30-D25 -> 14.7932 | E29: =E30-E25 -> -1574.2384 | F29: =F30-F25 -> -12865.25 | G29: =G30-G25 -> -580.4509 | H29: =H30-H25 -> 0 | I29: =I30-I25 -> 0 | J29: =J30-J25 -> 0 | K29: =K30-K25 -> 0 | L29: =L30-L25 -> -1.4551915e-11
B30: Diff in Reserve and surplus | D30: ='balance sheet1'!D76-'balance sheet1'!C76 -> 6539.03 | E30: ='balance sheet1'!E76-'balance sheet1'!D76 -> 6918.2 | F30: ='balance sheet1'!F76-'balance sheet1'!E76 -> -2960.54 | G30: ='balance sheet1'!G76-'balance sheet1'!F76 -> 11296.25 | H30: ='balance sheet1'!H76-'balance sheet1'!G76 -> 13280.684 | I30: ='balance sheet1'!I76-'balance sheet1'!H76 -> 13412.773 | J30: ='balance sheet1'!J76-'balance sheet1'!I76 -> 13171.059 | K30: ='balance sheet1'!K76-'balance sheet1'!J76 -> 11545.297 | L30: ='balance sheet1'!L76-'balance sheet1'!K76 -> 9694.1687

Sheet cashflow1
B3: Cash Flow Statement
B4: All the Figures In Crores
B5: Financial Year | C5: 44389 | D5: =C5+365 -> 44754 | E5: =D5+365 -> 45119 | F5: =E5+365 -> 45484 | G5: =F5+365 -> 45849 | H5: =G5+365 -> 46214 | I5: =H5+365 -> 46579 | J5: =I5+365 -> 46944 | K5: =J5+365 -> 47309 | L5: =K5+365 -> 47674
B6: Cash Flow From Operating Avtivities
B7: Net Income | C7: ='income statement'!C21 -> 8224.98 | D7: ='income statement'!D21 -> 10194.12 | E7: ='income statement'!E21 -> 12488.88 | F7: ='income statement'!F21 -> 15476.11 | G7: ='income statement'!G21 -> 17212.61 | H7: ='income statement'!H21 -> 20686.423 | I7: ='income statement'!I21 -> 20892.169 | J7: ='income statement'!J21 -> 20515.668 | ... L7: ='income statement'!L21 -> 15099.951
B8: Add: Depreciation | D8: ='income statement'!D16 -> 2947.95 | E8: ='income statement'!E16 -> 3502.25 | F8: ='income statement'!F16 -> 3682.33 | G8: ='income statement'!G16 -> 4121.18 | H8: ='income statement'!H16 -> 1111.1423 | I8: ='income statement'!I16 -> 1100.9859 | J8: ='income statement'!J16 -> 1078.0277 | K8: ='income statement'!K16 -> 1071.4437 | L8: ='income statement'!L16 -> 1051.1668
B9: Add: Interest | D9: ='income statement'!D18 -> 3125.7 | E9: ='income statement'!E18 -> 3207.16 | F9: ='income statement'!F18 -> 3545.85 | G9: ='income statement'!G18 -> 3334.37 | H9: ='income statement'!H18 -> 3734.2674 | I9: ='income statement'!I18 -> 2987.4139 | J9: ='income statement'!J18 -> 2240.5604 | K9: ='income statement'!K18 -> 1493.707 | L9: ='income statement'!L18 -> 746.85348
B10: Add: Tax | D10: ='income statement'!D20 -> 4216.61 | E10: ='income statement'!E20 -> 4484.16 | F10: ='income statement'!F20 -> 4947.39 | G10: ='income statement'!G20 -> 5891.4 | H10: ='income statement'!H20 -> 7427.506 | I10: ='income statement'!I20 -> 7501.3796 | J10: ='income statement'!J20 -> 7366.1959 | K10: ='income statement'!K20 -> 6456.9539 | L10: ='income statement'!L20 -> 5421.6709
B11: Inventories | D11: ='balance sheet1'!C7-'balance sheet1'!D7 -> -122.78 | E11: ='balance sheet1'!D7-'balance sheet1'!E7 -> -885.46 | F11: ='balance sheet1'!E7-'balance sheet1'!F7 -> 208.59 | G11: ='balance sheet1'!F7-'balance sheet1'!G7 -> -1050.36 | H11: ='balance sheet1'!G7-'balance sheet1'!H7 -> -3738.0926 | I11: ='balance sheet1'!H7-'balance sheet1'!I7 -> -1509.8265 | J11: ='balance sheet1'!I7-'balance sheet1'!J7 -> -1553.5189 | K11: ='balance sheet1'!J7-'balance sheet1'!K7 -> -1509.2237 | L11: ='balance sheet1'!K7-'balance sheet1'!L7 -> -1367.2756
B12: Trade receivables | D12: ='balance sheet1'!C9-'balance sheet1'!D9 -> -3909.54 | E12: ='balance sheet1'!D9-'balance sheet1'!E9 -> 1407.79 | F12: ='balance sheet1'!E9-'balance sheet1'!F9 -> -4039.42 | G12: ='balance sheet1'!F9-'balance sheet1'!G9 -> -4942.73 | H12: ='balance sheet1'!G9-'balance sheet1'!H9 -> -19911.059 | I12: ='balance sheet1'!H9-'balance sheet1'!I9 -> -8937.9786 | J12: ='balance sheet1'!I9-'balance sheet1'!J9 -> -9376.9625 | K12: ='balance sheet1'!J9-'balance sheet1'!K9 -> -8989.2693 | L12: ='balance sheet1'!K9-'balance sheet1'!L9 -> -8908.2918
B13: Other bank balances | D13: ='balance sheet1'!C11-'balance sheet1'!D11 -> -2314.95 | E13: ='balance sheet1'!D11-'balance sheet1'!E11 -> -409.98 | F13: ='balance sheet1'!E11-'balance sheet1'!F11 -> 2193.02 | G13: ='balance sheet1'!F11-'balance sheet1'!G11 -> -7378.45 | H13: ='balance sheet1'!G11-'balance sheet1'!H11 -> 2596.7346 | I13: ='balance sheet1'!H11-'balance sheet1'!I11 -> -993.2397 | J13: ='balance sheet1'!I11-'balance sheet1'!J11 -> -1042.0221 | K13: ='balance sheet1'!J11-'balance sheet1'!K11 -> -998.93942 | L13: ='balance sheet1'!K11-'balance sheet1'!L11 -> -989.94074
B14: Other financial assets | D14: ='balance sheet1'!C14-'balance sheet1'!D14 -> -404.14 | E14: ='balance sheet1'!D14-'balance sheet1'!E14 -> -1274.28 | F14: ='balance sheet1'!E14-'balance sheet1'!F14 -> -633.82 | G14: ='balance sheet1'!F14-'balance sheet1'!G14 -> 144.03 | H14: ='balance sheet1'!G14-'balance sheet1'!H14 -> 0 | I14: ='balance sheet1'!H14-'balance sheet1'!I14 -> 0 | J14: ='balance sheet1'!I14-'balance sheet1'!J14 -> 0 | K14: ='balance sheet1'!J14-'balance sheet1'!K14 -> 0 | L14: ='balance sheet1'!K14-'balance sheet1'!L14 -> 0
B15: Provisions | D15: ='balance sheet1'!D67-'balance sheet1'!C67 -> 43.99 | E15: ='balance sheet1'!E67-'balance sheet1'!D67 -> 52.22 | F15: ='balance sheet1'!F67-'balance sheet1'!E67 -> 117.39 | G15: ='balance sheet1'!G67-'balance sheet1'!F67 -> 136.63 | H15: ='balance sheet1'!H67-'balance sheet1'!G67 -> 0 | I15: ='balance sheet1'!I67-'balance sheet1'!H67 -> 0 | J15: ='balance sheet1'!J67-'balance sheet1'!I67 -> 0 | K15: ='balance sheet1'!K67-'balance sheet1'!J67 -> 0 | L15: ='balance sheet1'!L67-'balance sheet1'!K67 -> 0
B16: Other current assets | D16: ='balance sheet1'!C15-'balance sheet1'!D15 -> -5540.07 | E16: ='balance sheet1'!D15-'balance sheet1'!E15 -> -5588.84 | F16: ='balance sheet1'!E15-'balance sheet1'!F15 -> -5470.64 | G16: ='balance sheet1'!F15-'balance sheet1'!G15 -> -4168.8 | H16: ='balance sheet1'!G15-'balance sheet1'!H15 -> 0 | I16: ='balance sheet1'!H15-'balance sheet1'!I15 -> 0 | J16: ='balance sheet1'!I15-'balance sheet1'!J15 -> 0 | K16: ='balance sheet1'!J15-'balance sheet1'!K15 -> 0 | L16: ='balance sheet1'!K15-'balance sheet1'!L15 -> 0
B17: Due to micro and small enterprises | D17: ='balance sheet1'!D51-'balance sheet1'!C51 -> 86.92 | E17: ='balance sheet1'!E51-'balance sheet1'!D51 -> 275.79 | F17: ='balance sheet1'!F51-'balance sheet1'!E51 -> 167.01 | G17: ='balance sheet1'!G51-'balance sheet1'!F51 -> 398.94 | H17: ='balance sheet1'!H51-'balance sheet1'!G51 -> -91.076945 | I17: ='balance sheet1'!I51-'balance sheet1'!H51 -> 217.02884 | J17: ='balance sheet1'!J51-'balance sheet1'!I51 -> 243.63795 | K17: ='balance sheet1'!K51-'balance sheet1'!J51 -> 182.46641 | L17: ='balance sheet1'!L51-'balance sheet1'!K51 -> 188.2111
B18: Due to others | D18: ='balance sheet1'!D52-'balance sheet1'!C52 -> 5533.47 | E18: ='balance sheet1'!E52-'balance sheet1'!D52 -> -1857.29 | F18: ='balance sheet1'!F52-'balance sheet1'!E52 -> 3341.75 | G18: ='balance sheet1'!G52-'balance sheet1'!F52 -> -1232.48 | H18: ='balance sheet1'!H52-'balance sheet1'!G52 -> 31704.804 | I18: ='balance sheet1'!I52-'balance sheet1'!H52 -> 5723.5664 | J18: ='balance sheet1'!J52-'balance sheet1'!I52 -> 5076.6002 | K18: ='balance sheet1'!K52-'balance sheet1'!J52 -> 7512.9971 | L18: ='balance sheet1'!L52-'balance sheet1'!K52 -> 9653.6385
B19: Other financial liabilities | D19: ='balance sheet1'!D66-'balance sheet1'!C66 -> -63.8 | E19: ='balance sheet1'!E66-'balance sheet1'!D66 -> 150.02 | F19: ='balance sheet1'!F66-'balance sheet1'!E66 -> -176.89 | G19: ='balance sheet1'!G66-'balance sheet1'!F66 -> 156.11 | H19: ='balance sheet1'!H66-'balance sheet1'!G66 -> 0 | I19: ='balance sheet1'!I66-'balance sheet1'!H66 -> 0 | J19: ='balance sheet1'!J66-'balance sheet1'!I66 -> 0 | K19: ='balance sheet1'!K66-'balance sheet1'!J66 -> 0 | L19: ='balance sheet1'!L66-'balance sheet1'!K66 -> 0
B20: Deferred tax liabilities (net) | D20: ='balance sheet1'!D68-'balance sheet1'!C68 -> -139.33 | E20: ='balance sheet1'!E68-'balance sheet1'!D68 -> -408.9 | F20: ='balance sheet1'!F68-'balance sheet1'!E68 -> -96.8 | G20: ='balance sheet1'!G68-'balance sheet1'!F68 -> -123.62 | H20: ='balance sheet1'!H68-'balance sheet1'!G68 -> 331.04112 | I20: ='balance sheet1'!I68-'balance sheet1'!H68 -> 598.32296 | J20: ='balance sheet1'!J68-'balance sheet1'!I68 -> 1081.4075 | K20: ='balance sheet1'!K68-'balance sheet1'!J68 -> 1954.5335 | L20: ='balance sheet1'!L68-'balance sheet1'!K68 -> 3532.6193
B21: Other non-current liabilities | D21: ='balance sheet1'!D69-'balance sheet1'!C69 -> -47.43 | E21: ='balance sheet1'!E69-'balance sheet1'!D69 -> 60.46 | F21: ='balance sheet1'!F69-'balance sheet1'!E69 -> 536.29 | G21: ='balance sheet1'!G69-'balance sheet1'!F69 -> -23.28 | H21: ='balance sheet1'!H69-'balance sheet1'!G69 -> 0 | I21: ='balance sheet1'!I69-'balance sheet1'!H69 -> 0 | J21: ='balance sheet1'!J69-'balance sheet1'!I69 -> 0 | K21: ='balance sheet1'!K69-'balance sheet1'!J69 -> 0 | L21: ='balance sheet1'!L69-'balance sheet1'!K69 -> 0
B22: Other financial liabilities | D22: ='balance sheet1'!D54-'balance sheet1'!C54 -> 1335.42 | E22: ='balance sheet1'!E54-'balance sheet1'!D54 -> 777.59 | F22: ='balance sheet1'!F54-'balance sheet1'!E54 -> 133.73 | G22: ='balance sheet1'!G54-'balance sheet1'!F54 -> -1302.3 | H22: ='balance sheet1'!H54-'balance sheet1'!G54 -> 0 | I22: ='balance sheet1'!I54-'balance sheet1'!H54 -> 0 | J22: ='balance sheet1'!J54-'balance sheet1'!I54 -> 0 | K22: ='balance sheet1'!K54-'balance sheet1'!J54 -> 0 | L22: ='balance sheet1'!L54-'balance sheet1'!K54 -> 0
B23: Other current liabilities | D23: ='balance sheet1'!D55-'balance sheet1'!C55 -> 3139.11 | E23: ='balance sheet1'!E55-'balance sheet1'!D55 -> 7757.81 | F23: ='balance sheet1'!F55-'balance sheet1'!E55 -> 10017.53 | G23: ='balance sheet1'!G55-'balance sheet1'!F55 -> 11142.89 | H23: ='balance sheet1'!H55-'balance sheet1'!G55 -> 0 | I23: ='balance sheet1'!I55-'balance sheet1'!H55 -> 0 | J23: ='balance sheet1'!J55-'balance sheet1'!I55 -> 0 | K23: ='balance sheet1'!K55-'balance sheet1'!J55 -> 0 | L23: ='balance sheet1'!L55-'balance sheet1'!K55 -> 0
B24: Provisions | D24: ='balance sheet1'!D56-'balance sheet1'!C56 -> 357.18 | E24: ='balance sheet1'!E56-'balance sheet1'!D56 -> 137.61 | F24: ='balance sheet1'!F56-'balance sheet1'!E56 -> 622.42 | G24: ='balance sheet1'!G56-'balance sheet1'!F56 -> 575.78 | H24: ='balance sheet1'!H56-'balance sheet1'!G56 -> 0 | I24: ='balance sheet1'!I56-'balance sheet1'!H56 -> 0 | J24: ='balance sheet1'!J56-'balance sheet1'!I56 -> 0 | K24: ='balance sheet1'!K56-'balance sheet1'!J56 -> 0 | L24: ='balance sheet1'!L56-'balance sheet1'!K56 -> 0
B25: Current tax liabilities (net) | D25: ='balance sheet1'!D57-'balance sheet1'!C57 -> 138.8 | E25: ='balance sheet1'!E57-'balance sheet1'!D57 -> 83.64 | F25: ='balance sheet1'!F57-'balance sheet1'!E57 -> 467.01 | G25: ='balance sheet1'!G57-'balance sheet1'!F57 -> 718.74 | H25: ='balance sheet1'!H57-'balance sheet1'!G57 -> 0 | I25: ='balance sheet1'!I57-'balance sheet1'!H57 -> 0 | J25: ='balance sheet1'!J57-'balance sheet1'!I57 -> 0 | K25: ='balance sheet1'!K57-'balance sheet1'!J57 -> 0 | L25: ='balance sheet1'!L57-'balance sheet1'!K57 -> 0
B26: Net Cash Inflow/(Outflow) from Operating Activities | D26: =SUM(D7:D25) -> 18577.23 | E26: =SUM(E7:E25) -> 23960.63 | F26: =SUM(F7:F25) -> 35038.85 | G26: =SUM(G7:G25) -> 23610.66 | H26: =SUM(H7:H25) -> 43851.69 | I26: =SUM(I7:I25) -> 27579.822 | J26: =SUM(J7:J25) -> 25629.594 | K26: =SUM(K7:K25) -> 25157.998 | L26: =SUM(L7:L25) -> 24428.603
B28: Cash Flow From Investing Activities
B29: CapEx (Tangible Assets) | D29: ='balance sheet1'!C25-'balance sheet1'!D25-'bs drivers'!D184 -> -1547.25 | E29: ='balance sheet1'!D25-'balance sheet1'!E25-'bs drivers'!E184 -> -3029.79 | F29: ='balance sheet1'!E25-'balance sheet1'!F25-'bs drivers'!F184 -> -2827.88 | G29: ='balance sheet1'!F25-'balance sheet1'!G25-'bs drivers'!G184 -> -2661.42 | H29: ='balance sheet1'!G25-'balance sheet1'!H25-'bs drivers'!H184 -> -779.89651 | I29: ='balance sheet1'!H25-'balance sheet1'!I25-'bs drivers'!I184 -> -790.66403 | J29: ='balance sheet1'!I25-'balance sheet1'!J25-'bs drivers'!J184 -> -800.7121 | K29: ='balance sheet1'!J25-'balance sheet1'!K25-'bs drivers'!K184 -> -812.26969 | L29: ='balance sheet1'!K25-'balance sheet1'!L25-'bs drivers'!L184 -> -820.35947
B30: Addition (Intangible Assets) | D30: ='balance sheet1'!C28-'balance sheet1'!D28-'bs drivers'!D185 -> -408.18 | E30: ='balance sheet1'!D28-'balance sheet1'!E28-'bs drivers'!E185 -> -54.97 | F30: ='balance sheet1'!E28-'balance sheet1'!F28-'bs drivers'!F185 -> -920.11 | G30: ='balance sheet1'!F28-'balance sheet1'!G28-'bs drivers'!G185 -> -1757.42 | H30: ='balance sheet1'!G28-'balance sheet1'!H28-'bs drivers'!H185 -> -177.59234 | I30: ='balance sheet1'!H28-'balance sheet1'!I28-'bs drivers'!I185 -> -174.91125 | J30: ='balance sheet1'!I28-'balance sheet1'!J28-'bs drivers'!J185 -> -173.11721 | K30: ='balance sheet1'!J28-'balance sheet1'!K28-'bs drivers'!K185 -> -171.05886 | L30: ='balance sheet1'!K28-'balance sheet1'!L28-'bs drivers'!L185 -> -169.30628
B31: CapEx on other Fixed Assets | D31: ='balance sheet1'!C41-'balance sheet1'!D41 -> 3450.2 | E31: ='balance sheet1'!D41-'balance sheet1'!E41 -> 3298.68 | F31: ='balance sheet1'!E41-'balance sheet1'!F41 -> -13333.72 | G31: ='balance sheet1'!F41-'balance sheet1'!G41 -> -12337.36 | H31: ='balance sheet1'!G41-'balance sheet1'!H41 -> -4705.1497 | I31: ='balance sheet1'!H41-'balance sheet1'!I41 -> -5130.8187 | J31: ='balance sheet1'!I41-'balance sheet1'!J41 -> -5615.1813 | K31: ='balance sheet1'!J41-'balance sheet1'!K41 -> -6172.0242 | L31: ='balance sheet1'!K41-'balance sheet1'!L41 -> -6816.3165
B32: Investments | D32: ='balance sheet1'!C8-'balance sheet1'!D8 -> 1211.65 | E32: ='balance sheet1'!D8-'balance sheet1'!E8 -> -5773.84 | F32: ='balance sheet1'!E8-'balance sheet1'!F8 -> 615.79 | G32: ='balance sheet1'!F8-'balance sheet1'!G8 -> -8402.99 | H32: ='balance sheet1'!G8-'balance sheet1'!H8 -> -10717.85 | I32: ='balance sheet1'!H8-'balance sheet1'!I8 -> -6565.0786 | J32: ='balance sheet1'!I8-'balance sheet1'!J8 -> -6887.5189 | K32: ='balance sheet1'!J8-'balance sheet1'!K8 -> -6602.7524 | L32: ='balance sheet1'!K8-'balance sheet1'!L8 -> -6543.2733
B33: Loans towards financing activities | D33: ='balance sheet1'!C12-'balance sheet1'!D12 -> -890.17 | E33: ='balance sheet1'!D12-'balance sheet1'!E12 -> 1808.65 | F33: ='balance sheet1'!E12-'balance sheet1'!F12 -> 5645.96 | G33: ='balance sheet1'!F12-'balance sheet1'!G12 -> -1262.92 | H33: ='balance sheet1'!G12-'balance sheet1'!H12 -> 0 | I33: ='balance sheet1'!H12-'balance sheet1'!I12 -> 0 | J33: ='balance sheet1'!I12-'balance sheet1'!J12 -> 0 | K33: ='balance sheet1'!J12-'balance sheet1'!K12 -> 0 | L33: ='balance sheet1'!K12-'balance sheet1'!L12 -> 0
B34: Other loans | D34: ='balance sheet1'!C13-'balance sheet1'!D13 -> -44.99 | E34: ='balance sheet1'!D13-'balance sheet1'!E13 -> 29.19 | F34: ='balance sheet1'!E13-'balance sheet1'!F13 -> 144.61 | G34: ='balance sheet1'!F13-'balance sheet1'!G13 -> -310.31 | H34: ='balance sheet1'!G13-'balance sheet1'!H13 -> 0 | I34: ='balance sheet1'!H13-'balance sheet1'!I13 -> 0 | J34: ='balance sheet1'!I13-'balance sheet1'!J13 -> 0 | K34: ='balance sheet1'!J13-'balance sheet1'!K13 -> 0 | L34: ='balance sheet1'!K13-'balance sheet1'!L13 -> 0
B36: Group(s) of assets classified as held for sale | D36: ='balance sheet1'!C17-'balance sheet1'!D17 -> -824.54 | E36: ='balance sheet1'!D17-'balance sheet1'!E17 -> -158.02 | F36: ='balance sheet1'!E17-'balance sheet1'!F17 -> -16.56 | G36: ='balance sheet1'!F17-'balance sheet1'!G17 -> 847.92 | H36: ='balance sheet1'!G17-'balance sheet1'!H17 -> 0 | I36: ='balance sheet1'!H17-'balance sheet1'!I17 -> 0 | J36: ='balance sheet1'!I17-'balance sheet1'!J17 -> 0 | K36: ='balance sheet1'!J17-'balance sheet1'!K17 -> 0 | L36: ='balance sheet1'!K17-'balance sheet1'!L17 -> 0
B37: Liabilities associated with group(s) of assets classified as held for sale | D37: ='balance sheet1'!D59-'balance sheet1'!C59 -> 76.53 | E37: ='balance sheet1'!E59-'balance sheet1'!D59 -> -79.73 | F37: ='balance sheet1'!F59-'balance sheet1'!E59 -> 0 | G37: ='balance sheet1'!G59-'balance sheet1'!F59 -> 0 | H37: ='balance sheet1'!H59-'balance sheet1'!G59 -> 0 | I37: ='balance sheet1'!I59-'balance sheet1'!H59 -> 0 | J37: ='balance sheet1'!J59-'balance sheet1'!I59 -> 0 | K37: ='balance sheet1'!K59-'balance sheet1'!J59 -> 0 | L37: ='balance sheet1'!L59-'balance sheet1'!K59 -> 0
B38: Net Cash Inflow/(Outflow) from Investing Activities | D38: =SUM(D29:D37) -> 1023.25 | E38: =SUM(E29:E37) -> -3959.83 | F38: =SUM(F29:F37) -> -10691.91 | G38: =SUM(G29:G37) -> -25884.5 | H38: =SUM(H29:H37) -> -16380.488 | I38: =SUM(I29:I37) -> -12661.473 | J38: =SUM(J29:J37) -> -13476.529 | K38: =SUM(K29:K37) -> -13758.105 | L38: =SUM(L29:L37) -> -14349.256
B40: Cash Flow From Financing Activities
B41: Equity share capital | D41: ='balance sheet1'!D75-'balance sheet1'!C75 -> 0.1 | E41: ='balance sheet1'!E75-'balance sheet1'!D75 -> 0.09 | F41: ='balance sheet1'!F75-'balance sheet1'!E75 -> -6.17 | G41: ='balance sheet1'!G75-'balance sheet1'!F75 -> 0.11 | H41: ='balance sheet1'!H75-'balance sheet1'!G75 -> 0 | I41: ='balance sheet1'!I75-'balance sheet1'!H75 -> 0 | J41: ='balance sheet1'!J75-'balance sheet1'!I75 -> 0 | K41: ='balance sheet1'!K75-'balance sheet1'!J75 -> 0 | L41: ='balance sheet1'!L75-'balance sheet1'!K75 -> 0
B42: Non-controlling interests | D42: ='balance sheet1'!D78-'balance sheet1'!C78 -> 914.54 | E42: ='balance sheet1'!E78-'balance sheet1'!D78 -> 1275.2 | F42: ='balance sheet1'!F78-'balance sheet1'!E78 -> 1949.15 | G42: ='balance sheet1'!G78-'balance sheet1'!F78 -> 1557.66 | H42: ='balance sheet1'!H78-'balance sheet1'!G78 -> 0 | I42: ='balance sheet1'!I78-'balance sheet1'!H78 -> 0 | J42: ='balance sheet1'!J78-'balance sheet1'!I78 -> 0 | K42: ='balance sheet1'!K78-'balance sheet1'!J78 -> 0 | L42: ='balance sheet1'!L78-'balance sheet1'!K78 -> 0
B43: Borrowings | D43: ='balance sheet1'!D64-'balance sheet1'!C64 -> -20501.73 | E43: ='balance sheet1'!E64-'balance sheet1'!D64 -> -400.63 | F43: ='balance sheet1'!F64-'balance sheet1'!E64 -> -4710.71 | G43: ='balance sheet1'!G64-'balance sheet1'!F64 -> 996.37 | H43: ='balance sheet1'!H64-'balance sheet1'!G64 -> 499.332 | I43: ='balance sheet1'!I64-'balance sheet1'!H64 -> -14500.668 | J43: ='balance sheet1'!J64-'balance sheet1'!I64 -> -14500.668 | K43: ='balance sheet1'!K64-'balance sheet1'!J64 -> -14500.668 | L43: ='balance sheet1'!L64-'balance sheet1'!K64 -> -14500.668
B44: Lease liabilities | D44: ='balance sheet1'!D65-'balance sheet1'!C65 -> 15.59 | E44: ='balance sheet1'!E65-'balance sheet1'!D65 -> 13 | F44: ='balance sheet1'!F65-'balance sheet1'!E65 -> 88.47 | G44: ='balance sheet1'!G65-'balance sheet1'!F65 -> 530.46 | H44: ='balance sheet1'!H65-'balance sheet1'!G65 -> 485.64695 | I44: ='balance sheet1'!I65-'balance sheet1'!H65 -> 187.14854 | J44: ='balance sheet1'!J65-'balance sheet1'!I65 -> 235.61695 | K44: ='balance sheet1'!K65-'balance sheet1'!J65 -> 298.62464 | L44: ='balance sheet1'!L65-'balance sheet1'!K65 -> 391.21278
B45: Borrowings | D45: ='balance sheet1'!D47-'balance sheet1'!C47 -> 2711.13 | E45: ='balance sheet1'!E47-'balance sheet1'!D47 -> 419.36 | F45: ='balance sheet1'!F47-'balance sheet1'!E47 -> -3062.05 | G45: ='balance sheet1'!G47-'balance sheet1'!F47 -> 8027.03 | H45: ='balance sheet1'!H47-'balance sheet1'!G47 -> 5211.2102 | I45: ='balance sheet1'!I47-'balance sheet1'!H47 -> 6071.7076 | J45: ='balance sheet1'!J47-'balance sheet1'!I47 -> 7076.8188 | K45: ='balance sheet1'!K47-'balance sheet1'!J47 -> 8251.1379 | L45: ='balance sheet1'!L47-'balance sheet1'!K47 -> 9623.4742
...

Sheet balance sheet1
L2: Index!A1
B3: Balance Sheet
B4: All the Figures In Crores
B5: Financial Year | C5: 44389 | D5: =C5+365 -> 44754 | E5: =D5+365 -> 45119 | F5: =E5+365 -> 45484 | G5: =F5+365 -> 45849 | H5: =G5+365 -> 46214 | I5: =H5+365 -> 46579 | J5: =I5+365 -> 46944 | K5: =J5+365 -> 47309 | L5: =K5+365 -> 47674
B6: Current Assets
B7: Inventories | C7: =bs!B25 -> 5820.54 | D7: =bs!C25 -> 5943.32 | E7: =bs!D25 -> 6828.78 | F7: =bs!E25 -> 6620.19 | G7: =bs!F25 -> 7670.55 | H7: ='bs drivers'!H6 -> 11408.643 | I7: ='bs drivers'!I6 -> 12918.469 | J7: ='bs drivers'!J6 -> 14471.988 | K7: ='bs drivers'!K6 -> 15981.212 | L7: ='bs drivers'!L6 -> 17348.487
B8: Investments | C8: =bs!B26 -> 31011.23 | D8: =bs!C26 -> 29799.58 | E8: =bs!D26 -> 35573.42 | F8: =bs!E26 -> 34957.63 | G8: =bs!F26 -> 43360.62 | H8: ='bs drivers'!H10 -> 54078.47 | I8: ='bs drivers'!I10 -> 60643.548 | J8: ='bs drivers'!J10 -> 67531.067 | K8: ='bs drivers'!K10 -> 74133.82 | L8: ='bs drivers'!L10 -> 80677.093
B9: Trade receivables | C9: =bs!B27 -> 42229.78 | D9: =bs!C27 -> 46139.32 | E9: =bs!D27 -> 44731.53 | F9: =bs!E27 -> 48770.95 | G9: =bs!F27 -> 53713.68 | H9: ='bs drivers'!H14 -> 73624.739 | I9: ='bs drivers'!I14 -> 82562.718 | J9: ='bs drivers'!J14 -> 91939.68 | K9: ='bs drivers'!K14 -> 100928.95 | L9: ='bs drivers'!L14 -> 109837.24
B10: Cash and cash equivalents | C10: =bs!B28 -> 13373.52 | D10: =bs!C28 -> 13770.24 | E10: =bs!D28 -> 16926.69 | F10: =bs!E28 -> 11958.5 | G10: =bs!F28 -> 12187 | H10: =cashflow1!H56 -> 18720.631 | I10: =cashflow1!I56 -> 2373.0428 | J10: =cashflow1!J56 -> -16918.508 | K10: =cashflow1!K56 -> -32942.504 | L10: =cashflow1!L56 -> -46469.894
B11: Other bank balances | C11: =bs!B29 -> 2867.98 | D11: =bs!C29 -> 5182.93 | E11: =bs!D29 -> 5592.91 | F11: =bs!E29 -> 3399.89 | G11: =bs!F29 -> 10778.34 | H11: ='bs drivers'!H18 -> 8181.6054 | I11: ='bs drivers'!I18 -> 9174.8451 | J11: ='bs drivers'!J18 -> 10216.867 | K11: ='bs drivers'!K18 -> 11215.807 | L11: ='bs drivers'!L18 -> 12205.747
B12: Loans towards financing activities | C12: =bs!B30 -> 41379.03 | D12: =bs!C30 -> 42269.2 | E12: =bs!D30 -> 40460.55 | F12: =bs!E30 -> 34814.59 | G12: =bs!F30 -> 36077.51 | H12: ='bs drivers'!H22 -> 36077.51 | I12: ='bs drivers'!I22 -> 36077.51 | J12: ='bs drivers'!J22 -> 36077.51 | K12: ='bs drivers'!K22 -> 36077.51 | L12: ='bs drivers'!L22 -> 36077.51
B13: Other loans | C13: =bs!B31 -> 235.35 | D13: =bs!C31 -> 280.34 | E13: =bs!D31 -> 251.15 | F13: =bs!E31 -> 106.54 | G13: =bs!F31 -> 416.85 | H13: ='bs drivers'!H24 -> 416.85 | I13: ='bs drivers'!I24 -> 416.85 | J13: ='bs drivers'!J24 -> 416.85 | K13: ='bs drivers'!K24 -> 416.85 | L13: ='bs drivers'!L24 -> 416.85
B14: Other financial assets | C14: =bs!B32 -> 3251.68 | D14: =bs!C32 -> 3655.82 | E14: =bs!D32 -> 4930.1 | F14: =bs!E32 -> 5563.92 | G14: =bs!F32 -> 5419.89 | H14: ='bs drivers'!H26 -> 5419.89 | I14: ='bs drivers'!I26 -> 5419.89 | J14: ='bs drivers'!J26 -> 5419.89 | K14: ='bs drivers'!K26 -> 5419.89 | L14: ='bs drivers'!L26 -> 5419.89
B15: Other current assets | C15: =bs!B33 -> 54791.48 | D15: =bs!C33 -> 60331.55 | E15: =bs!D33 -> 65920.39 | F15: =bs!E33 -> 71391.03 | G15: =bs!F33 -> 75559.83 | H15: ='bs drivers'!H28 -> 75559.83 | I15: ='bs drivers'!I28 -> 75559.83 | J15: ='bs drivers'!J28 -> 75559.83 | K15: ='bs drivers'!K28 -> 75559.83 | L15: ='bs drivers'!L28 -> 75559.83
B16: Sub-total Current Assets | C16: =SUM(C7:C15) -> 194960.59 | D16: =SUM(D7:D15) -> 207372.3 | E16: =SUM(E7:E15) -> 221215.52 | F16: =SUM(F7:F15) -> 217583.24 | G16: =SUM(G7:G15) -> 245184.27 | H16: =SUM(H7:H15) -> 283488.17 | I16: =SUM(I7:I15) -> 285146.7 | J16: =SUM(J7:J15) -> 284715.17 | ... L16: =SUM(L7:L15) -> 291072.75
B17: Group(s) of assets classified as held for sale | C17: =bs!B35 -> 6.24 | D17: =bs!C35 -> 830.78 | E17: =bs!D35 -> 988.8 | F17: =bs!E35 -> 1005.36 | G17: =bs!F35 -> 157.44 | H17: =G17 -> 157.44 | I17: =H17 -> 157.44 | J17: =I17 -> 157.44 | K17: =J17 -> 157.44 | L17: =K17 -> 157.44
B20: Total Current Assets | C20: =C16+C17 -> 194966.83 | D20: =D16+D17 -> 208203.08 | E20: =E16+E17 -> 222204.32 | F20: =F16+F17 -> 218588.6 | G20: =G16+G17 -> 245341.71 | H20: =H16+H17 -> 283645.61 | I20: =I16+I17 -> 285304.14 | J20: =J16+J17 -> 284872.61 | ... L20: =L16+L17 -> 291230.19
B22: Non-Current Assets
B23: Property, plant & equipment | C23: =bs!B7 -> 11386.29 | D23: =bs!C7 -> 10577.98 | E23: =bs!D7 -> 11336.28 | F23: =bs!E7 -> 13297.64 | G23: =bs!F7 -> 14128.56 | H23: ='bs drivers'!H58 -> 14043.766 | I23: ='bs drivers'!I58 -> 13974.033 | J23: ='bs drivers'!J58 -> 13932.585 | K23: ='bs drivers'!K58 -> 13904.398 | L23: ='bs drivers'!L58 -> 13900.171
B24: Investment property | C24: =bs!B9 -> 3646.78 | D24: =bs!C9 -> 3962.98 | E24: =bs!D9 -> 3360.22 | F24: =bs!E9 -> 1936.44 | G24: =bs!F9 -> 1157.33 | H24: ='bs drivers'!H75 -> 1099.4635 | I24: ='bs drivers'!I75 -> 1044.4903 | J24: ='bs drivers'!J75 -> 992.26581 | K24: ='bs drivers'!K75 -> 942.65252 | L24: ='bs drivers'!L75 -> 895.51989
B25: Total Tangible Assets | C25: =SUM(C23:C24) -> 15033.07 | D25: =SUM(D23:D24) -> 14540.96 | E25: =SUM(E23:E24) -> 14696.5 | F25: =SUM(F23:F24) -> 15234.08 | G25: =SUM(G23:G24) -> 15285.89 | H25: =SUM(H23:H24) -> 15143.23 | I25: =SUM(I23:I24) -> 15018.523 | J25: =SUM(J23:J24) -> 14924.851 | ... L25: =SUM(L23:L24) -> 14795.691
B26: Other intangible assets | C26: =bs!B12 -> 19197.76 | D26: =bs!C12 -> 18729.37 | E26: =bs!D12 -> 18007.98 | F26: =bs!E12 -> 17384.52 | G26: =bs!F12 -> 17050.76 | H26: ='bs drivers'!H91 -> 17050.76 | I26: ='bs drivers'!I91 -> 17050.76 | J26: ='bs drivers'!J91 -> 17050.76 | K26: ='bs drivers'!K91 -> 17050.76 | L26: ='bs drivers'!L91 -> 17050.76
B27: Right-of-use assets | C27: =bs!B14 -> 2021.53 | D27: =bs!C14 -> 1989.51 | E27: =bs!D14 -> 2137.87 | F27: =bs!E14 -> 2289.41 | G27: =bs!F14 -> 2869.02 | H27: ='bs drivers'!H99 -> 2858.027 | I27: ='bs drivers'!I99 -> 2847.3225 | J27: ='bs drivers'!J99 -> 2836.7969 | K27: ='bs drivers'!K99 -> 2826.4821 | L27: ='bs drivers'!L99 -> 2816.3406
B28: Total Intangible Assets | C28: =SUM(C26:C27) -> 21219.29 | D28: =SUM(D26:D27) -> 20718.88 | E28: =SUM(E26:E27) -> 20145.85 | F28: =SUM(F26:F27) -> 19673.93 | G28: =SUM(G26:G27) -> 19919.78 | H28: =SUM(H26:H27) -> 19908.787 | I28: =SUM(I26:I27) -> 19898.082 | J28: =SUM(J26:J27) -> 19887.557 | ... L28: =SUM(L26:L27) -> 19867.101
B29: Capital work-in-progress | C29: =bs!B8 -> 388.37 | D29: =bs!C8 -> 1170.32 | E29: =bs!D8 -> 2949.09 | F29: =bs!E8 -> 2897.04 | G29: =bs!F8 -> 2390.86 | H29: ='bs drivers'!H67 -> 2990.0095 | I29: ='bs drivers'!I67 -> 3739.6049 | J29: ='bs drivers'!J67 -> 4677.4978 | K29: ='bs drivers'!K67 -> 5851.082 | L29: ='bs drivers'!L67 -> 7320.2887
B30: Investment property under construction | C30: =bs!B10 -> 0 | D30: =bs!C10 -> 0 | E30: =bs!D10 -> 0 | F30: =bs!E10 -> 254.93 | G30: =bs!F10 -> 501.3 | H30: ='bs drivers'!H125 -> 501.3 | I30: ='bs drivers'!I125 -> 501.3 | J30: ='bs drivers'!J125 -> 501.3 | K30: ='bs drivers'!K125 -> 501.3 | L30: ='bs drivers'!L125 -> 501.3
B31: Goodwill | C31: =bs!B11 -> 8066.96 | D31: =bs!C11 -> 7685.17 | E31: =bs!D11 -> 7798.65 | F31: =bs!E11 -> 7800.88 | G31: =bs!F11 -> 8348.48 | H31: ='bs drivers'!H83 -> 8348.48 | I31: ='bs drivers'!I83 -> 8348.48 | J31: ='bs drivers'!J83 -> 8348.48 | K31: ='bs drivers'!K83 -> 8348.48 | L31: ='bs drivers'!L83 -> 8348.48
B32: Intangible assets under development | C32: =bs!B13 -> 112.02 | D32: =bs!C13 -> 79.23 | E32: =bs!D13 -> 116.48 | F32: =bs!E13 -> 147.97 | G32: =bs!F13 -> 197.82 | H32: ='bs drivers'!H139 -> 227.11714 | I32: ='bs drivers'!I139 -> 263.97825 | J32: ='bs drivers'!J139 -> 307.1123 | K32: ='bs drivers'!K139 -> 357.20232 | L32: ='bs drivers'!L139 -> 414.81905
B33: Investments in joint ventures & associates | C33: =bs!B15 -> 2670.26 | D33: =bs!C15 -> 2521.16 | E33: =bs!D15 -> 1304.86 | F33: =bs!E15 -> 1264.25 | G33: =bs!F15 -> 2318.42 | H33: ='bs drivers'!H107 -> 2318.42 | I33: ='bs drivers'!I107 -> 2318.42 | J33: ='bs drivers'!J107 -> 2318.42 | K33: ='bs drivers'!K107 -> 2318.42 | L33: ='bs drivers'!L107 -> 2318.42
B34: Other investments | C34: =bs!B16 -> 5945.14 | D34: =bs!C16 -> 7074.44 | E34: =bs!D16 -> 7920.03 | F34: =bs!E16 -> 9425.94 | G34: =bs!F16 -> 9126.23 | H34: ='bs drivers'!H115 -> 10158.407 | I34: ='bs drivers'!I115 -> 11307.322 | J34: ='bs drivers'!J115 -> 12586.181 | K34: ='bs drivers'!K115 -> 14009.678 | L34: ='bs drivers'!L115 -> 15594.172
B35: Loans towards financing activities | C35: =bs!B17 -> 52631.67 | D35: =bs!C17 -> 46736.84 | E35: =bs!D17 -> 40920.92 | F35: =bs!E17 -> 52154.76 | G35: =bs!F17 -> 62847.35 | H35: ='bs drivers'!H123 -> 65694.335 | I35: ='bs drivers'!I123 -> 68670.288 | J35: ='bs drivers'!J123 -> 71781.052 | K35: ='bs drivers'!K123 -> 75032.734 | L35: ='bs drivers'!L123 -> 78431.717
B36: Other loans | C36: =bs!B18 -> 173.24 | D36: =bs!C18 -> 284.54 | E36: =bs!D18 -> 356 | F36: =bs!E18 -> 475.46 | G36: =bs!F18 -> 348.96 | H36: ='bs drivers'!H147 -> 415.71605 | I36: ='bs drivers'!I147 -> 495.24253 | J36: ='bs drivers'!J147 -> 589.98242 | K36: ='bs drivers'!K147 -> 702.84606 | L36: ='bs drivers'!L147 -> 837.30051
B37: Other financial assets | C37: =bs!B19 -> 1420.19 | D37: =bs!C19 -> 2134.9 | E37: =bs!D19 -> 1965.78 | F37: =bs!E19 -> 1952.08 | G37: =bs!F19 -> 1863.04 | H37: ='bs drivers'!H155 -> 1993.8254 | I37: ='bs drivers'!I155 -> 2133.792 | J37: ='bs drivers'!J155 -> 2283.5841 | K37: ='bs drivers'!K155 -> 2443.8918 | L37: ='bs drivers'!L155 -> 2615.453
B38: Deferred tax assets (net) | C38: =bs!B20 -> 2697 | D38: =bs!C20 -> 2840.1 | E38: =bs!D20 -> 3984.79 | F38: =bs!E20 -> 3863.72 | G38: =bs!F20 -> 3792.88 | H38: =G38 -> 3792.88 | I38: =H38 -> 3792.88 | J38: =I38 -> 3792.88 | K38: =J38 -> 3792.88 | L38: =K38 -> 3792.88
B39: Current Tax Assets (net) | C39: =bs!B21 -> 0 | D39: =bs!C21 -> 0 | E39: =bs!D21 -> 3611.66 | F39: =bs!E21 -> 4245.78 | G39: =bs!F21 -> 4581.6 | H39: =G39 -> 4581.6 | I39: =H39 -> 4581.6 | J39: =I39 -> 4581.6 | K39: =J39 -> 4581.6 | L39: =K39 -> 4581.6
B40: Other non-current assets | C40: =bs!B22 -> 5949.67 | D40: =bs!C22 -> 6077.62 | E40: =bs!D22 -> 2377.38 | F40: =bs!E22 -> 2156.55 | G40: =bs!F22 -> 2659.78 | H40: ='bs drivers'!H176 -> 2659.78 | I40: ='bs drivers'!I176 -> 2659.78 | J40: ='bs drivers'!J176 -> 2659.78 | K40: ='bs drivers'!K176 -> 2659.78 | L40: ='bs drivers'!L176 -> 2659.78
B41: Total Other Fixed Assets: | C41: =SUM(C29:C40) -> 80054.52 | D41: =SUM(D29:D40) -> 76604.32 | E41: =SUM(E29:E40) -> 73305.64 | F41: =SUM(F29:F40) -> 86639.36 | G41: =SUM(G29:G40) -> 98976.72 | H41: =SUM(H29:H40) -> 103681.87 | I41: =SUM(I29:I40) -> 108812.69 | J41: =SUM(J29:J40) -> 114427.87 | ... L41: =SUM(L29:L40) -> 127416.21
B43: Total Non-Current Assets | C43: =C25+C28+C41 -> 116306.88 | D43: =D25+D28+D41 -> 111864.16 | E43: =E25+E28+E41 -> 108147.99 | F43: =F25+F28+F41 -> 121547.37 | G43: =G25+G28+G41 -> 134182.39 | H43: =H25+H28+H41 -> 138733.89 | I43: =I25+I28+I41 -> 143729.29 | J43: =J25+J28+J41 -> 149240.28 | ... L43: =L25+L28+L41 -> 162079
B44: Total Assets | C44: =C20+C43 -> 311273.71 | D44: =D20+D43 -> 320067.24 | E44: =E20+E43 -> 330352.31 | F44: =F20+F43 -> 340135.97 | G44: =G20+G43 -> 379524.1 | H44: =H20+H43 -> 422379.49 | I44: =I20+I43 -> 429033.44 | J44: =J20+J43 -> 434112.89 | ... L44: =L20+L43 -> 453309.2
B46: Current Liabilities
...

Sheet valuation->

Sheet wacc
B2: Weigheted Average Cost Of Capital
B3: All the figures in Rs Crores
B4: Weigheted Average Cost of Capital
B6: Equity (Cr) | D6: ='balance sheet1'!G79 -> 115403.68
B7: Debt (cr) | D7: ='balance sheet1'!G64+'balance sheet1'!G47 -> 93364.64
B9: Cost of Debt | D9: ='income statement'!C18/wacc!D7 -> 0.041915655
B10: Tax Rate | D10: ='p&L drivers'!G26 -> 0.2549947
B11: D/(D+E) | D11: =D7/(D6+D7) -> 0.44721651
B12: After Tax Cost of Debt | D12: =D9*(1-D10) -> 0.031227385
B14: Risk Free Rate (10 yr Treasury Yield) | D14: 0.065
B15: Expected Market Return | D15: 0.1259
B16: Market Risk Premium | D16: =D15-D14 -> 0.0609
B17: Beta | D17: 1
B18: E/(D+E) | D18: =1-D11 -> 0.55278349
B19: Cost of Equity | D19: =D14+(D17*D16) -> 0.1259
B21: WACC | D21: 0.081574162

Sheet dcf
L1: Index!A1
B2: Discounted Cash Flow Model
B3: All the Figures In Crores
B4: Financial Year | C4: 44389 | D4: 44754 | E4: 45119 | F4: 45484 | G4: 45849 | H4: 46214 | I4: 46579 | J4: 46944 | K4: 47309 | L4: 47674
B5: Unlevered Free Cash Flow | D5: =cashflow1!D26-cashflow1!D29-cashflow1!D30 -> 20532.66 | E5: =cashflow1!E26-cashflow1!E29-cashflow1!E30 -> 27045.39 | F5: =cashflow1!F26-cashflow1!F29-cashflow1!F30 -> 38786.84 | G5: =cashflow1!G26-cashflow1!G29-cashflow1!G30 -> 28029.5 | H5: =cashflow1!H26-cashflow1!H29-cashflow1!H30 -> 44809.179 | I5: =cashflow1!I26-cashflow1!I29-cashflow1!I30 -> 28545.397 | J5: =cashflow1!J26-cashflow1!J29-cashflow1!J30 -> 26603.423 | K5: =cashflow1!K26-cashflow1!K29-cashflow1!K30 -> 26141.326 | L5: =cashflow1!L26-cashflow1!L29-cashflow1!L30 -> 25418.269
K6: TV | L6: =L5*(1+C14)/(C15-C14) -> 845285.53
B8: Projection Year | G8: 0 | H8: 1 | I8: 2 | J8: 3 | K8: 4 | L8: 5
B9: Present Value of the Free Cash Flow | H9: =PV($C$15,H8,,-H5,) -> 41429.594 | I9: =PV($C$15,I8,,-I5,) -> 24401.891 | J9: =PV($C$15,J8,,-J5,) -> 21026.579 | K9: =PV($C$15,K8,,-K5,) -> 19103.036 | L9: =PV($C$15,L8,,-L5,) -> 17173.723
K10: pv year tv | L10: =PV(C15,L8,,-L6) -> 571112.83
B12: Implied Share Price Calculation
B13: Sum of PV of FCF | C13: =SUM(H9:L9) -> 123134.82 | F13: Sensitivity Table
B14: Growth Rate | C14: 0.05
B15: WACC | C15: =wacc!D21 -> 0.081574162 | H15: Growth
B16: Terminal Value | C16: =L6 -> 845285.53 | G16: =C24 -> 4328.051 | H16: 0.04 | I16: 0.045 | J16: 0.05 | K16: 0.055 | L16: 0.06
B17: PV of Terminal Value | C17: =L10 -> 571112.83 | F17: WACC | G17: 0.071574162 | H17: 4505.6634 | I17: 5340.8357 | J17: 6563.125 | K17: 8522.881 | L17: 12175.853
B18: Enterprice Value | C18: =C17+C13 -> 694247.65 | G18: 0.076574162 | H18: 3820.2216 | I18: 4415.8486 | J18: 5235.6134 | K18: 6435.3534 | L18: 8358.955
B19: (+) Cash | C19: ='balance sheet1'!G10 -> 12187 | G19: 0.081574162 | H19: 3299.3104 | I19: 3743.3619 | J19: 4328.051 | K19: 5132.7618 | L19: 6310.4701
B20: (-) Debt | C20: =wacc!D7 -> 93364.64 | G20: 0.086574162 | H20: 2889.946 | I20: 3232.2803 | J20: 3668.2147 | K20: 4242.2158 | L20: 5032.2166
B21: (-) Minority Interest | C21: ='balance sheet1'!G78 -> 17748.08 | G21: 0.091574162 | H21: 2559.6912 | I21: 2830.6269 | J21: 3166.7319 | K21: 3594.7337 | L21: 4158.2899
B22: Equity Value | C22: =C18+C19-C20-C21 -> 595321.93
B23: Diluted Shares Outstanding (cr.) | C23: =cca!E7 -> 137.54966
B24: Implied Share Price | C24: =C22/C23 -> 4328.051

Sheet cca
Q1: Index!A1
B2: Comperable Companies analysis
B3: All the figures in Rs Crores
C4: Market Data | K4: Financials | O4: Valuation
B5: Company | C5: Share Price (Rs./Share) | D5: Equity Value (Market Cap) | E5: No of Shares Outstanding | F5: Debt | G5: Cash Equal | H5: Net Debt | I5: Enterprice Value | K5: Revenue | L5: EBITDA | M5: Net Icome | O5: EV/Reveneu | P5: EV/EBITDA | Q5: P/E
B7: Larsen & Toubro | C7: 4068 | D7: 559552 | E7: =D7/C7 -> 137.54966 | F7: 134001.13 | G7: 22965.34 | H7: =F7-G7 -> 111035.79 | I7: =D7+H7 -> 670587.79 | K7: 255734.45 | L7: 37922.33 | M7: 17673.33 | O7: =I7/K7 -> 2.6222036 | P7: =I7/L7 -> 17.683191 | Q7: =D7/M7 -> 31.660813
